<?xml version="1.0" encoding="utf-8"?>
<!-- This URDF was automatically created by SolidWorks to URDF Exporter! Originally created by Stephen Brawner (brawner@gmail.com) 
     Commit Version: 1.5.0-0-g9aa0fdb  Build Version: 1.5.7004.21443
     For more information, please see http://wiki.ros.org/sw_urdf_exporter -->
<robot
  name="scrubber_model" xmlns:xacro="http://ros.org/wiki/xacro">
  <xacro:include filename="$(find scrubber_model)/urdf/scrubber_model.gazebo.xacro"/>
  <xacro:include filename="$(find scrubber_model)/urdf/common_properties.xacro"/>
  <xacro:include filename="$(find scrubber_model)/urdf/scrubber_tof_model_plugin.xacro"/>
  
  <link
    name="base_link">
    <inertial>
      <origin
        xyz="0.091674 -0.0063891 0.27463"
        rpy="0 0 0" />
      <mass
        value="41.078" />
      <inertia
        ixx="3.3108"
        ixy="0.0075275"
        ixz="-0.016249"
        iyy="3.705"
        iyz="0.0030066"
        izz="4.3412" />
    </inertial>
    <visual>
      <origin
        xyz="0 0 0"
        rpy="0 0 0" />
      <geometry>
        <mesh
          filename="package://scrubber_model/meshes/base_link.STL" />
      </geometry>
      <material
        name="">
        <color
          rgba="1 1 0.9451 1" />
      </material>
    </visual>
    <collision>
      <origin
        xyz="0 0 0"
        rpy="0 0 0" />
      <geometry>
        <mesh
          filename="package://scrubber_model/meshes/base_link.STL" />
      </geometry>
    </collision>
  </link>

  <link
    name="right_wheel_Link">
    <inertial>
      <origin
        xyz="0.00072363 0.025159 -0.00044959"
        rpy="0 0 0" />
      <mass
        value="1.2908" />
      <inertia
        ixx="0.0047721"
        ixy="-2.0541E-08"
        ixz="2.143E-08"
        iyy="0.0091542"
        iyz="-1.7861E-08"
        izz="0.0047721" />
    </inertial>
    <visual>
      <origin
        xyz="0 0 0"
        rpy="0 0 0" />
      <geometry>
        <mesh
          filename="package://scrubber_model/meshes/right_wheel_Link.STL" />
      </geometry>
      <material
        name="">
        <color
          rgba="0.79216 0.81961 0.93333 1" />
      </material>
    </visual>
    <collision>
      <origin
        xyz="0 0 0"
        rpy="0 0 0" />
      <geometry>
        <mesh
          filename="package://scrubber_model/meshes/right_wheel_Link.STL" />
      </geometry>
    </collision>
  </link>
  <joint
    name="joint_rw"
    type="continuous">
    <origin
      xyz="-0.025721 -0.3659 -0.059548"
      rpy="0 0 0" />
    <parent
      link="base_link" />
    <child
      link="right_wheel_Link" />
    <axis
      xyz="0 1 0" />
    <limit
      lower="-180"
      upper="180"
      effort="0"
      velocity="0" />
    <safety_controller
      k_velocity="0" />
  </joint>
  <link
    name="left_wheel_Link">
    <inertial>
      <origin
        xyz="0.000723629156446026 -0.0251587992443347 -0.000449587030259595"
        rpy="0 0 0" />
      <mass
        value="1.29080749046176" />
      <inertia
        ixx="0.00477207493749581"
        ixy="2.05463192574373E-08"
        ixz="2.14307565239151E-08"
        iyy="0.00915424015488939"
        iyz="1.78550627756218E-08"
        izz="0.00477206891888719" />
    </inertial>
    <visual>
      <origin
        xyz="0 0 0"
        rpy="0 0 0" />
      <geometry>
        <mesh
          filename="package://scrubber_model/meshes/left_wheel_Link.STL" />
      </geometry>
      <material
        name="">
        <color
          rgba="0.792156862745098 0.819607843137255 0.933333333333333 1" />
      </material>
    </visual>
    <collision>
      <origin
        xyz="0 0 0"
        rpy="0 0 0" />
      <geometry>
        <mesh
          filename="package://scrubber_model/meshes/left_wheel_Link.STL" />
      </geometry>
    </collision>
  </link>
  <joint
    name="joint_lw"
    type="continuous">
    <origin
      xyz="-0.025721 0.3659 -0.059548"
      rpy="0 0 0" />
    <parent
      link="base_link" />
    <child
      link="left_wheel_Link" />
    <axis
      xyz="0 1 0" />
    <limit
      lower="-180"
      upper="180"
      effort="0"
      velocity="0" />
    <safety_controller
      k_velocity="0" />
  </joint>
  <link
    name="universal_wheel_Link">
    <inertial>
      <origin
        xyz="0.017103 -0.00048419 -0.017874"
        rpy="0 0 0" />
      <mass
        value="0.087047" />
      <inertia
        ixx="7.582E-05"
        ixy="9.1298E-09"
        ixz="2.0695E-05"
        iyy="7.4394E-05"
        iyz="-5.4645E-10"
        izz="8.3633E-05" />
    </inertial>
    <visual>
      <origin
        xyz="0 0 0"
        rpy="0 0 0" />
      <geometry>
        <mesh
          filename="package://scrubber_model/meshes/universal_wheel_Link.STL" />
      </geometry>
      <material
        name="">
        <color
          rgba="1 1 0.52941 1" />
      </material>
    </visual>
    <collision>
      <origin
        xyz="0 0 0"
        rpy="0 0 0" />
      <geometry>
        <mesh
          filename="package://scrubber_model/meshes/universal_wheel_Link.STL" />
      </geometry>
    </collision>
  </link>
  <joint
    name="joint_uw"
    type="continuous">
    <origin
      xyz="0.479 2.5E-05 -0.06"
      rpy="0 0 0" />
    <parent
      link="base_link" />
    <child
      link="universal_wheel_Link" />
    <axis
      xyz="0 0 1" />
    <limit
      lower="-180"
      upper="180"
      effort="0"
      velocity="0" />
    <safety_controller
      k_velocity="0" />
  </joint>
  <link
    name="front_wheel_Link">
    <inertial>
      <origin
        xyz="2.2204E-16 0.044 2.0262E-15"
        rpy="0 0 0" />
      <mass
        value="0.25282" />
      <inertia
        ixx="0.00017792"
        ixy="-6.9773E-20"
        ixz="-3.4963E-10"
        iyy="0.00030873"
        iyz="1.8907E-19"
        izz="0.00017793" />
    </inertial>
    <visual>
      <origin
        xyz="0 0 0"
        rpy="0 0 0" />
      <geometry>
        <mesh
          filename="package://scrubber_model/meshes/front_wheel_Link.STL" />
      </geometry>
      <material
        name="">
        <color
          rgba="0.63922 0.63922 0.63922 1" />
      </material>
    </visual>
    <collision>
      <origin
        xyz="0 0 0"
        rpy="0 0 0" />
      <geometry>
        <mesh
          filename="package://scrubber_model/meshes/front_wheel_Link.STL" />
      </geometry>
    </collision>
  </link>
  <joint
    name="joint_fw"
    type="continuous">
    <origin
      xyz="0.04 -0.044 -0.06"
      rpy="0 0 0" />
    <parent
      link="universal_wheel_Link" />
    <child
      link="front_wheel_Link" />
    <axis
      xyz="0 1 0" />
    <limit
      lower="-180"
      upper="180"
      effort="0"
      velocity="0" />
    <safety_controller
      k_velocity="0" />
  </joint>
  <link
    name="laser">
    <inertial>
      <origin
        xyz="-0.012 1.7967E-17 0"
        rpy="0 0 0" />
      <mass
        value="0.20534" />
      <inertia
        ixx="0.00039166"
        ixy="-4.8439E-21"
        ixz="-5.5057E-22"
        iyy="7.5635E-05"
        iyz="-5.0613E-20"
        izz="0.00033574" />
    </inertial>
    <visual>
      <origin
        xyz="0 0 0"
        rpy="0 0 0" />
      <geometry>
        <mesh
          filename="package://scrubber_model/meshes/ladar_Link.STL" />
      </geometry>
      <material
        name="">
        <color
          rgba="0.75294 0.75294 0.75294 1" />
      </material>
    </visual>
    <collision>
      <origin
        xyz="0 0 0"
        rpy="0 0 0" />
      <geometry>
        <mesh
          filename="package://scrubber_model/meshes/ladar_Link.STL" />
      </geometry>
    </collision>
  </link>
  <joint
    name="joint_ladar"
    type="fixed">
    <origin
      xyz="0.65 0 0.2"
      rpy="0 0 2.967" />
    <parent
      link="base_link" />
    <child
      link="laser" />
    <axis
      xyz="0 0 0" />
    <safety_controller
      k_velocity="0" />
  </joint>
  <link
    name="imu_Link">
    <inertial>
      <origin
        xyz="0 1.18E-19 -0.018"
        rpy="0 0 0" />
      <mass
        value="0.25841" />
      <inertia
        ixx="0.00014583"
        ixy="-1.1463E-20"
        ixz="1.6094E-21"
        iyy="0.00023052"
        iyz="-7.0586E-21"
        izz="0.00032053" />
    </inertial>
    <visual>
      <origin
        xyz="0 0 0"
        rpy="0 0 0" />
      <geometry>
        <mesh
          filename="package://scrubber_model/meshes/imu_Link.STL" />
      </geometry>
      <material
        name="">
        <color
          rgba="0.75294 0.75294 0.75294 1" />
      </material>
    </visual>
    <collision>
      <origin
        xyz="0 0 0"
        rpy="0 0 0" />
      <geometry>
        <mesh
          filename="package://scrubber_model/meshes/imu_Link.STL" />
      </geometry>
    </collision>
  </link>
  <joint
    name="joint_imu"
    type="fixed">
    <origin
      xyz="-0.0235 0 0.08"
      rpy="0 0 0" />
    <parent
      link="base_link" />
    <child
      link="imu_Link" />
    <axis
      xyz="0 0 0" />
    <safety_controller
      k_velocity="0" />
  </joint>
  
  <!--Back-->
  <link name="ultrasonic_1">
    <collision>
      <origin xyz="0 0 0" rpy="0 0 0"/>
      <geometry>
        <box size="0.01 0.01 0.01"/>
      </geometry>
    </collision>
    <visual>
      <origin xyz="0 0 0" rpy="0 0 0"/>
      <geometry>
        <box size="0.01 0.01 0.01"/>
      </geometry>
    </visual>
    <inertial>
      <mass value="1e-5" />
      <origin xyz="0 0 0" rpy="0 0 0"/>
      <inertia ixx="1e-6" ixy="0" ixz="0" iyy="1e-6" iyz="0" izz="1e-6" />
    </inertial>  
  </link>

  <joint name="joint_ultrasonic_1" type="fixed">
    <origin xyz="-0.39717 0 0.28128" rpy="0 -0.1745 3.14159" />
    <parent link="base_link" />
    <child link="ultrasonic_1" />
    <axis xyz="0 0 0" />
    <safety_controller k_velocity="0" />
  </joint>

  <link name="ultrasonic_2">
    <collision>
      <origin xyz="0 0 0" rpy="0 0 0"/>
      <geometry>
        <box size="0.01 0.01 0.01"/>
      </geometry>
    </collision>
    <visual>
      <origin xyz="0 0 0" rpy="0 0 0"/>
      <geometry>
        <box size="0.01 0.01 0.01"/>
      </geometry>
    </visual>
    <inertial>
      <mass value="1e-5" />
      <origin xyz="0 0 0" rpy="0 0 0"/>
      <inertia ixx="1e-6" ixy="0" ixz="0" iyy="1e-6" iyz="0" izz="1e-6" />
    </inertial>  
  </link>

  <joint name="joint_ultrasonic_2" type="fixed">
    <origin xyz="-0.14684 -0.3545 0.2812" rpy="0 -0.1745 -2.002590784" />
    <parent link="base_link" />
    <child link="ultrasonic_2" />
    <axis xyz="0 0 0" />
    <safety_controller k_velocity="0" />
  </joint>

  <link name="ultrasonic_7">
    <collision>
      <origin xyz="0 0 0" rpy="0 0 0"/>
      <geometry>
        <box size="0.01 0.01 0.01"/>
      </geometry>
    </collision>
    <visual>
      <origin xyz="0 0 0" rpy="0 0 0"/>
      <geometry>
        <box size="0.01 0.01 0.01"/>
      </geometry>
    </visual>
    <inertial>
      <mass value="1e-5" />
      <origin xyz="0 0 0" rpy="0 0 0"/>
      <inertia ixx="1e-6" ixy="0" ixz="0" iyy="1e-6" iyz="0" izz="1e-6" />
    </inertial>  
  </link>

  <joint name="joint_ultrasonic_7"
    type="fixed">
    <origin xyz="-0.15684 0.3645 0.2812" rpy="0 -0.1745 2.002590784" />
    <parent link="base_link" />
    <child link="ultrasonic_7" />
    <axis xyz="0 0 0" />
    <safety_controller k_velocity="0" />
  </joint>

  <link name="ultrasonic_3">
    <collision>
      <origin xyz="0 0 0" rpy="0 0 0"/>
      <geometry>
        <box size="0.01 0.01 0.01"/>
      </geometry>
    </collision>
    <visual>
      <origin xyz="0 0 0" rpy="0 0 0"/>
      <geometry>
        <box size="0.01 0.01 0.01"/>
      </geometry>
    </visual>
    <inertial>
      <mass value="1e-5" />
      <origin xyz="0 0 0" rpy="0 0 0"/>
      <inertia ixx="1e-6" ixy="0" ixz="0" iyy="1e-6" iyz="0" izz="1e-6" />
    </inertial>  
  </link>

  <joint name="joint_ultrasonic_3" type="fixed">
    <origin xyz="0.31689 -0.37496 0.28112" rpy="0 -0.1745 -1.254717199" />
    <parent link="base_link" />
    <child link="ultrasonic_3" />
    <axis xyz="0 0 0" />
    <safety_controller k_velocity="0" />
  </joint>
  
  <link name="ultrasonic_6">
    <collision>
      <origin xyz="0 0 0" rpy="0 0 0"/>
      <geometry>
        <box size="0.01 0.01 0.01"/>
      </geometry>
    </collision>
    <visual>
      <origin xyz="0 0 0" rpy="0 0 0"/>
      <geometry>
        <box size="0.01 0.01 0.01"/>
      </geometry>
    </visual>
    <inertial>
      <mass value="1e-5" />
      <origin xyz="0 0 0" rpy="0 0 0"/>
      <inertia ixx="1e-6" ixy="0" ixz="0" iyy="1e-6" iyz="0" izz="1e-6" />
    </inertial>  
  </link>

  <joint name="joint_ultrasonic_6" type="fixed">
    <origin xyz="0.31689 0.37496 0.28112" rpy="0 -0.1745 1.254717199" />
    <parent link="base_link" />
    <child link="ultrasonic_6" />
    <axis xyz="0 0 0" />
    <safety_controller k_velocity="0" />
  </joint>
  
  <link name="ultrasonic_4">
    <collision>
      <origin xyz="0 0 0" rpy="0 0 0"/>
      <geometry>
        <box size="0.01 0.01 0.01"/>
      </geometry>
    </collision>
    <visual>
      <origin xyz="0 0 0" rpy="0 0 0"/>
      <geometry>
        <box size="0.01 0.01 0.01"/>
      </geometry>
    </visual>
    <inertial>
      <mass value="1e-5" />
      <origin xyz="0 0 0" rpy="0 0 0"/>
      <inertia ixx="1e-6" ixy="0" ixz="0" iyy="1e-6" iyz="0" izz="1e-6" />
    </inertial>  
  </link>

  <joint name="joint_ultrasonic_4" type="fixed">
    <origin xyz="0.53838 -0.21984 0.31164" rpy="0 -0.1745 -0.51190507" />
    <parent link="base_link" />
    <child link="ultrasonic_4" />
    <axis xyz="0 0 0" />
    <safety_controller k_velocity="0" />
  </joint>
  
  <link name="ultrasonic_5">
    <collision>
      <origin xyz="0 0 0" rpy="0 0 0"/>
      <geometry>
        <box size="0.01 0.01 0.01"/>
      </geometry>
    </collision>
    <visual>
      <origin xyz="0 0 0" rpy="0 0 0"/>
      <geometry>
        <box size="0.01 0.01 0.01"/>
      </geometry>
    </visual>
    <inertial>
      <mass value="1e-5" />
      <origin xyz="0 0 0" rpy="0 0 0"/>
      <inertia ixx="1e-6" ixy="0" ixz="0" iyy="1e-6" iyz="0" izz="1e-6" />
    </inertial>  
  </link>

  <joint name="joint_ultrasonic_5" type="fixed">
    <origin xyz="0.53838 0.21984 0.31164" rpy="0 -0.1745 0.51190507" />
    <parent link="base_link" />
    <child link="ultrasonic_5" />
    <axis xyz="0 0 0" />
    <safety_controller k_velocity="0" />
  </joint>
  
  <!-- Camera -->
<joint name="camera_base_joint" type="fixed">
    <axis xyz="0 0 0" />
    <origin xyz="0.6 0 0.75" rpy="0 0 0"/>
    <parent link="base_link"/>
    <child link="camera_base"/>
  </joint>

  
  <link name="camera_base">
    <collision>
      <origin xyz="0 0 0" rpy="0 -1.57 0"/>
      <geometry>
    <box size="0.05 0.05 0.05"/>
      </geometry>
    </collision>

    <visual>
      <origin xyz="0 0 0" rpy="0 0 0"/>
      <geometry>
    <box size="0.05 0.05 0.05"/>
      </geometry>
      <material name="red"/>
    </visual>

    <inertial>
      <mass value="1e-5" />
      <origin xyz="0 0 0" rpy="0 0 0"/>
      <inertia ixx="1e-6" ixy="0" ixz="0" iyy="1e-6" iyz="0" izz="1e-6" />
    </inertial>
  </link>

  <joint name="camera_joint" type="fixed">
    <axis xyz="0 0 0" />
    <origin xyz="0.0 0 0.0" rpy="-1.57 0 -1.57"/>
    <parent link="camera_base"/>
    <child link="camera_link"/>
  </joint>

  
  <link name="camera_link">
    <collision>
      <origin xyz="0 0 0" rpy="0 0 0"/>
      <geometry>
    <box size="0.05 0.05 0.05"/>
      </geometry>
    </collision>

    <visual>
      <origin xyz="0 0 0" rpy="0 0 0"/>
      <geometry>
    <box size="0.05 0.05 0.05"/>
      </geometry>
      <material name="red"/>
    </visual>

    <inertial>
      <mass value="1e-5" />
      <origin xyz="0 0 0" rpy="0 0 0"/>
      <inertia ixx="1e-6" ixy="0" ixz="0" iyy="1e-6" iyz="0" izz="1e-6" />
    </inertial>
  </link>

  <!-- TOF -->
  <joint name="tof_front_base_joint" type="fixed">
    <axis xyz="0 0 0" />
    <origin xyz="0.58575 -0.007 0.52975" rpy="0 0 0"/>
    <parent link="base_link"/>
    <child link="tof_front_base"/>
  </joint>
  
  <link name="tof_front_base">
    <collision>
      <origin xyz="0 0 0" rpy="0 -1.57 0"/>
      <geometry>
    <box size="0.05 0.05 0.05"/>
      </geometry>
    </collision>
    <visual>
      <origin xyz="0 0 0" rpy="0 0 0"/>
      <geometry>
    <box size="0.05 0.05 0.05"/>
      </geometry>
      <material name="blue"/>
    </visual>
    <inertial>
      <mass value="1e-5" />
      <origin xyz="0 0 0" rpy="0 0 0"/>
      <inertia ixx="1e-6" ixy="0" ixz="0" iyy="1e-6" iyz="0" izz="1e-6" />
    </inertial>
  </link>

  <link name="tof_front_link"/>
  <joint name="joint_tof_front_cloud" type="fixed">
    <parent link="tof_front_base"/>
    <child link="tof_front_link"/>
    <origin xyz="0 0 0" rpy="-1.8326 0 -1.57"/>
  </joint>

  <joint name="tof_left_base_joint" type="fixed">
    <axis xyz="0 0 0" />
    <origin xyz="0.44717 0.31657 0.81" rpy="0 0 0.5682"/>
    <parent link="base_link"/>
    <child link="tof_left_base"/>
  </joint>
  
  <link name="tof_left_base">
    <collision>
      <origin xyz="0 0 0" rpy="0 -1.57 0"/>
      <geometry>
    <box size="0.05 0.05 0.05"/>
      </geometry>
    </collision>
    <visual>
      <origin xyz="0 0 0" rpy="0 0 0"/>
      <geometry>
    <box size="0.05 0.05 0.05"/>
      </geometry>
      <material name="blue"/>
    </visual>
    <inertial>
      <mass value="1e-5" />
      <origin xyz="0 0 0" rpy="0 0 0"/>
      <inertia ixx="1e-6" ixy="0" ixz="0" iyy="1e-6" iyz="0" izz="1e-6" />
    </inertial>
  </link>

  <link name="tof_left_link"/>
  <joint name="joint_tof_left_cloud" type="fixed">
    <parent link="tof_left_base"/>
    <child link="tof_left_link"/>
    <origin xyz="0 0 0" rpy="-1.57 0 -1.57"/>
  </joint>



  <joint name="tof_right_base_joint" type="fixed">
    <axis xyz="0 0 0" />
    <origin xyz="0.4354 -0.3241 0.81" rpy="0 0 -0.5682"/>
    <parent link="base_link"/>
    <child link="tof_right_base"/>
  </joint>
  
  <link name="tof_right_base">
    <collision>
      <origin xyz="0 0 0" rpy="0 -1.57 0"/>
      <geometry>
    <box size="0.05 0.05 0.05"/>
      </geometry>
    </collision>
    <visual>
      <origin xyz="0 0 0" rpy="0 0 0"/>
      <geometry>
    <box size="0.05 0.05 0.05"/>
      </geometry>
      <material name="blue"/>
    </visual>
    <inertial>
      <mass value="1e-5" />
      <origin xyz="0 0 0" rpy="0 0 0"/>
      <inertia ixx="1e-6" ixy="0" ixz="0" iyy="1e-6" iyz="0" izz="1e-6" />
    </inertial>
  </link>

  <link name="tof_right_link"/>
  <joint name="joint_tof_right_cloud" type="fixed">
    <parent link="tof_right_base"/>
    <child link="tof_right_link"/>
    <origin xyz="0 0 0" rpy="-1.57 0 -1.57"/>
  </joint>


  <joint name="tof_back_base_joint" type="fixed">
    <axis xyz="0 0 0" />
    <origin xyz="-0.35008 0.007 0.81" rpy="0 0 3.14"/>
    <parent link="base_link"/>
    <child link="tof_back_base"/>
  </joint>
  
  <link name="tof_back_base">
    <collision>
      <origin xyz="0 0 0" rpy="0 -1.57 0"/>
      <geometry>
    <box size="0.05 0.05 0.05"/>
      </geometry>
    </collision>
    <visual>
      <origin xyz="0 0 0" rpy="0 0 0"/>
      <geometry>
    <box size="0.05 0.05 0.05"/>
      </geometry>
      <material name="blue"/>
    </visual>
    <inertial>
      <mass value="1e-5" />
      <origin xyz="0 0 0" rpy="0 0 0"/>
      <inertia ixx="1e-6" ixy="0" ixz="0" iyy="1e-6" iyz="0" izz="1e-6" />
    </inertial>
  </link>

  <link name="tof_back_link"/>
  <joint name="joint_tof_back_cloud" type="fixed">
    <parent link="tof_back_base"/>
    <child link="tof_back_link"/>
    <origin xyz="0 0 0" rpy="-1.8326 0 -1.57"/>
  </joint>

  
  <!-- mmWave -->
      <link name="mmwave_link">
        <collision>
          <origin xyz="0 0 0" rpy="0 -1.57 0"/>
          <geometry>
        <box size="0.05 0.05 0.05"/>
          </geometry>
        </collision>

        <visual>
          <origin xyz="0 0 0" rpy="0 0 0"/>
          <geometry>
        <box size="0.05 0.05 0.05"/>
          </geometry>
          <material name="red"/>
        </visual>

        <inertial>
          <mass value="1e-5" />
          <origin xyz="0 0 0" rpy="0 0 0"/>
          <inertia ixx="1e-6" ixy="0" ixz="0" iyy="1e-6" iyz="0" izz="1e-6" />
        </inertial>
      </link>

      <joint name="mmwave_link_joint" type="fixed">
        <axis xyz="0 0 0" />
        <origin xyz="0.5718 0 0.5775" rpy="0 0 0"/>
        <parent link="base_link"/>
        <child link="mmwave_link"/>
      </joint>
</robot>
